Workbook

Sheet Raw Data
AC3: Men vs Women | AI3: Average Age | AU3: Average Income | AV3: Car Value | AW3: Ave value of one car | BG3: Avg income per county | DD3: Avg income per sector | DK3: % of people having debts than their annual income | DP3: Avg age of people with net worth higher than their income
B4: gender | C4: age | D4: field of work | E4: Column1 | F4: Column2 | G4: Education | H4: kids | I4: Vehicles | J4: income | K4: Column3 | L4: County | M4: Value of House | N4: Mortage Left | O4: Car Value | P4: Car Debt | Q4: Debts | R4: Investments | S4: Value of the person | T4: Value of Debts | U4: Net Worth (£) | W4: Field of work | AA4: Counties | AC4: Men | AD4: Women | AF4: Number of Men | AG4: Number of Women | AI4: =AVERAGE(Table1[age]) -> 37.141717 | AJ4: Health | AK4: Construction | AL4: Technology | AM4: Education | AN4: Agriculture | AO4: Social Service | AP4: No of Health | AQ4: No of Construction | AR4: No of Education | AS4: No of Agriculture | AT4: No of Social Service | AU4: =AVERAGE(Table1[income]) -> 64113.473 | AV4: =(O5/I5) -> 8525.6449 | AW4: =AVERAGE(AV4:AV504) -> 31737.773 | AX4: Debt Amount | AY4: 100000 | AZ4: No of people with debts greater than X | BA4: =SUM(AX5:AX504) -> 414 | BB4: % left to pay | BC4: less than | BD4: 0.3 | BE4: No of people have less than X% left to pay | BF4: =SUM(BC5:BC504) -> 167 | BG4: Cumbria | BH4: Cheshire | BI4: Bristol | BJ4: Surrey | BK4: Norfolk | BL4: Lincolnshire | BM4: Somerset | BN4: Cambridgeshire | BO4: South Yorkshire | BP4: Greater London | BQ4: Hampshire | BR4: Gloucestershire | BS4: West Sussex | BT4: Devon | BU4: Berkshire | BV4: Staffordshire | BW4: Leicestershire | BX4: Cornwall | BY4: isle of Wight | BZ4: Surrey | CA4: Derbyshire | CB4: City of London | CC4: Bedfordshire | CD4: County Durham | CE4: East Riding of Yorkshire | CF4: West Yorkshire | CG4: Essex | CH4: East Sussex | CI4: Greater Manchester | CJ4: Hertfordshire | CK4: Herefordshire | CL4: Lancashire | CM4: Merseyside | CN4: Northamptonshire | CO4: Northumberland | CP4: Wiltshire | CQ4: West Midlands | CR4: Warwickshire | CS4: Tyne and Wear | CT4: Worcestershire | CU4: Rutland | CV4: Shropshire | CW4: Dorset | CX4: Buckinghamshire | CY4: Suffolk | CZ4: North Yorkshire | DA4: Kent | DB4: Derbyshire | DD4: Health | DE4: Agriculture | DF4: Technology | DG4: Social Service | DH4: Education | DI4: Construction
A5: =RANDBETWEEN(1,2) -> 2 | B5: =IF(A5=1, "men", "women") -> women | C5: =RANDBETWEEN(25,50) -> 50 | D5: =RANDBETWEEN(1,6) -> 3 | E5: =VLOOKUP(D5,$W$5:$X$10,2) -> Education | F5: =RANDBETWEEN(1,5) -> 4 | G5: =VLOOKUP(F5,$Y$5:$Z$9,2) -> Technical | H5: =RANDBETWEEN(0,4) -> 0 | I5: =RANDBETWEEN(1,3) -> 2 | J5: =RANDBETWEEN(30000,100000) -> 32071 | K5: =RANDBETWEEN(1,48) -> 26 | L5: =VLOOKUP(K5,$AA$5:$AB$52,2) -> Leicestershire | M5: =J5*(RANDBETWEEN(2,5)) -> 128284 | N5: =RAND()*M5 -> 15780.6 | O5: =I5*RAND()*J5 -> 17051.29 | P5: =RANDBETWEEN(0,O5) -> 10411 | Q5: =RAND()*J5*2 -> 61142.263 | R5: =RAND()*J5*1.5 -> 401.89115 | S5: =J5+R5+O5 -> 49524.181 | T5: =N5+P5+Q5 -> 87333.863 | U5: =S5-T5 -> -37809.682 | W5: 1 | X5: Health | Y5: 1 | Z5: High School | AA5: 1 | AB5: Bedfordshire | AC5: =IF(Table1[[#This Row],[gender]]="men",1,0) -> 0 | AD5: =IF(Table1[[#This Row],[gender]]="women",1,0) -> 1 | AF5: =SUM(AC5:AC505) -> 245 | AG5: =SUM(AD5:AD505) -> 256 | AJ5: =IF(Table1[[#This Row],[Column1]]="Health",1,0) -> 0 | AK5: =IF(Table1[[#This Row],[Column1]]="Construction",1,0) -> 0 | AL5: =IF(Table1[[#This Row],[Column1]]="Technology",1,0) -> 0 | AM5: =IF(Table1[[#This Row],[Column1]]="Education",1,0) -> 1 | AN5: =IF(Table1[[#This Row],[Column1]]="Agriculture",1,0) -> 0 | AO5: =IF(Table1[[#This Row],[Column1]]="Social Service", 1, 0) -> 0 | AP5: =SUM(AJ5:AJ505) -> 96 | AQ5: =SUM(AK5:AK505) -> 72 | AR5: =SUM(AM5:AM505) -> 91 | AS5: =SUM(AN5:AN505) -> 87 | AT5: =SUM(AO5:AO505) -> 87 | AV5: =(O6/I6) -> 65000.31 | AX5: =IF(Table1[[#This Row],[Value of Debts]]>$AY$4,1,0) -> 0 | BB5: =Table1[[#This Row],[Mortage Left]]/Table1[[#This Row],[Value of House]] -> 0.123013 | BC5: =IF(BB5<$BD$4,1,0) -> 1 | BG5: =IF(Table1[[#This Row],[County]]="Cumbria",Table1[[#This Row],[income]],0) -> 0 | BH5: =IF(Table1[[#This Row],[County]]="Cheshire",Table1[[#This Row],[income]],0) -> 0 | BI5: =IF(Table1[[#This Row],[County]]="Bristol",Table1[[#This Row],[income]],0) -> 0 | BJ5: =IF(Table1[[#This Row],[County]]="Surrey",Table1[[#This Row],[income]],0) -> 0 | BK5: =IF(Table1[[#This Row],[County]]="Norfolk",Table1[[#This Row],[income]],0) -> 0 | BL5: =IF(Table1[[#This Row],[County]]="Lincolnshire",Table1[[#This Row],[income]],0) -> 0 | BM5: =IF(Table1[[#This Row],[County]]="Somerset",Table1[[#This Row],[income]],0) -> 0 | BN5: =IF(Table1[[#This Row],[County]]="Cambridgeshire",Table1[[#This Row],[income]],0) -> 0 | BO5: =IF(Table1[[#This Row],[County]]="South Yorkshire",Table1[[#This Row],[income]],0) -> 0 | BP5: =IF(Table1[[#This Row],[County]]="Greater London",Table1[[#This Row],[income]],0) -> 0 | BQ5: =IF(Table1[[#This Row],[County]]="Hampshire",Table1[[#This Row],[income]],0) -> 0 | BR5: =IF(Table1[[#This Row],[County]]="Gloucestershire",Table1[[#This Row],[income]],0) -> 0 | BS5: =IF(Table1[[#This Row],[County]]="West Sussex",Table1[[#This Row],[income]],0) -> 0 | BT5: =IF(Table1[[#This Row],[County]]="Devon",Table1[[#This Row],[income]],0) -> 0 | BU5: =IF(Table1[[#This Row],[County]]="Berkshire",Table1[[#This Row],[income]],0) -> 0 | BV5: =IF(Table1[[#This Row],[County]]="Staffordshire",Table1[[#This Row],[income]],0) -> 0 | BW5: =IF(Table1[[#This Row],[County]]="Leicestershire",Table1[[#This Row],[income]],0) -> 32071 | BX5: =IF(Table1[[#This Row],[County]]="Cornwall",Table1[[#This Row],[income]],0) -> 0 | BY5: =IF(Table1[[#This Row],[County]]="Isle of Wight",Table1[[#This Row],[income]],0) -> 0 | BZ5: =IF(Table1[[#This Row],[County]]="Surrey",Table1[[#This Row],[income]],0) -> 0 | CA5: =IF(Table1[[#This Row],[County]]="Derbyshire",Table1[[#This Row],[income]],0) -> 0 | CB5: =IF(Table1[[#This Row],[County]]="City of London",Table1[[#This Row],[income]],0) -> 0 | CC5: =IF(Table1[[#This Row],[County]]="Bedfordshire",Table1[[#This Row],[income]],0) -> 0 | CD5: =IF(Table1[[#This Row],[County]]="County Durham",Table1[[#This Row],[income]],0) -> 0 | CE5: =IF(Table1[[#This Row],[County]]="East Riding of Yorkshire",Table1[[#This Row],[income]],0) -> 0 | CF5: =IF(Table1[[#This Row],[County]]="West Yorkshire",Table1[[#This Row],[income]],0) -> 0 | CG5: =IF(Table1[[#This Row],[County]]="Essex",Table1[[#This Row],[income]],0) -> 0 | CH5: =IF(Table1[[#This Row],[County]]="East Sussex",Table1[[#This Row],[income]],0) -> 0 | CI5: =IF(Table1[[#This Row],[County]]="Greater Manchester",Table1[[#This Row],[income]],0) -> 0 | CJ5: =IF(Table1[[#This Row],[County]]="Hertfordshire",Table1[[#This Row],[income]],0) -> 0 | CK5: =IF(Table1[[#This Row],[County]]="Herefordshire",Table1[[#This Row],[income]],0) -> 0 | CL5: =IF(Table1[[#This Row],[County]]="Lancashire",Table1[[#This Row],[income]],0) -> 0 | CM5: =IF(Table1[[#This Row],[County]]="Merseyside",Table1[[#This Row],[income]],0) -> 0 | CN5: =IF(Table1[[#This Row],[County]]="Northamptonshire",Table1[[#This Row],[income]],0) -> 0 | CO5: =IF(Table1[[#This Row],[County]]="Northumberland",Table1[[#This Row],[income]],0) -> 0 | CP5: =IF(Table1[[#This Row],[County]]="Wiltshire",Table1[[#This Row],[income]],0) -> 0 | CQ5: =IF(Table1[[#This Row],[County]]="West Midlands",Table1[[#This Row],[income]],0) -> 0 | CR5: =IF(Table1[[#This Row],[County]]="Warwickshire",Table1[[#This Row],[income]],0) -> 0 | CS5: =IF(Table1[[#This Row],[County]]="Tyne and Wear",Table1[[#This Row],[income]],0) -> 0 | CT5: =IF(Table1[[#This Row],[County]]="Worcestershire",Table1[[#This Row],[income]],0) -> 0 | CU5: =IF(Table1[[#This Row],[County]]="Rutland",Table1[[#This Row],[income]],0) -> 0 | CV5: =IF(Table1[[#This Row],[County]]="Shropshire",Table1[[#This Row],[income]],0) -> 0 | CW5: =IF(Table1[[#This Row],[County]]="Dorset",Table1[[#This Row],[income]],0) -> 0 | CX5: =IF(Table1[[#This Row],[County]]="Buckinghamshire",Table1[[#This Row],[income]],0) -> 0 | CY5: =IF(Table1[[#This Row],[County]]="Suffolk",Table1[[#This Row],[income]],0) -> 0 | CZ5: =IF(Table1[[#This Row],[County]]="North Yorkshire",Table1[[#This Row],[income]],0) -> 0 | DA5: =IF(Table1[[#This Row],[County]]="Kent",Table1[[#This Row],[income]],0) -> 0 | DB5: =IF(Table1[[#This Row],[County]]="Derbyshire",Table1[[#This Row],[income]],0) -> 0 | DD5: =IF(Table1[[#This Row],[Column1]]="Health",Table1[[#This Row],[income]],0) -> 0 | DE5: =IF(Table1[[#This Row],[Column1]]="Agriculture",Table1[[#This Row],[income]],0) -> 0 | DF5: =IF(Table1[[#This Row],[Column1]]="Technology",Table1[[#This Row],[income]],0) -> 0 | DG5: =IF(Table1[[#This Row],[Column1]]="Social Service",Table1[[#This Row],[income]],0) -> 0 | DH5: =IF(Table1[[#This Row],[Column1]]="Education",Table1[[#This Row],[income]],0) -> 32071 | DI5: =IF(Table1[[#This Row],[Column1]]="Construction",Table1[[#This Row],[income]],0) -> 0 | DK5: =IF(Table1[[#This Row],[Value of Debts]]>Table1[[#This Row],[income]],1,0) -> 1 | DM5: =SUM(DK5:DK504)/COUNT(DK5:DK504) -> 0.952 | DP5: =IF(Table1[[#This Row],[Net Worth (£)]]>$DS$5,C5,0) -> 0 | DS5: 50000
A6: =RANDBETWEEN(1,2) -> 2 | B6: =IF(A6=1, "men", "women") -> women | C6: =RANDBETWEEN(25,50) -> 29 | D6: =RANDBETWEEN(1,6) -> 3 | E6: =VLOOKUP(D6,$W$5:$X$10,2) -> Education | F6: =RANDBETWEEN(1,5) -> 5 | G6: =VLOOKUP(F6,$Y$5:$Z$9,2) -> Other | H6: =RANDBETWEEN(0,4) -> 2 | I6: =RANDBETWEEN(1,3) -> 3 | J6: =RANDBETWEEN(30000,100000) -> 81268 | K6: =RANDBETWEEN(1,48) -> 25 | L6: =VLOOKUP(K6,$AA$5:$AB$52,2) -> Lancashire | M6: =J6*(RANDBETWEEN(2,5)) -> 243804 | N6: =RAND()*M6 -> 125405.09 | O6: =I6*RAND()*J6 -> 195000.93 | P6: =RANDBETWEEN(0,O6) -> 133945 | Q6: =RAND()*J6*2 -> 41593.447 | R6: =RAND()*J6*1.5 -> 22387.006 | S6: =J6+R6+O6 -> 298655.94 | T6: =N6+P6+Q6 -> 300943.53 | U6: =S6-T6 -> -2287.5965 | W6: 2 | X6: Construction | Y6: 2 | Z6: College | AA6: 2 | AB6: Berkshire | AC6: =IF(Table1[[#This Row],[gender]]="men",1,0) -> 0 | AD6: =IF(Table1[[#This Row],[gender]]="women",1,0) -> 1 | AJ6: =IF(Table1[[#This Row],[Column1]]="Health",1,0) -> 0 | AK6: =IF(Table1[[#This Row],[Column1]]="Construction",1,0) -> 0 | AL6: =IF(Table1[[#This Row],[Column1]]="Technology",1,0) -> 0 | AM6: =IF(Table1[[#This Row],[Column1]]="Education",1,0) -> 1 | AN6: =IF(Table1[[#This Row],[Column1]]="Agriculture",1,0) -> 0 | AO6: =IF(Table1[[#This Row],[Column1]]="Social Service", 1, 0) -> 0 | AV6: =(O7/I7) -> 34097.394 | AX6: =IF(Table1[[#This Row],[Value of Debts]]>$AY$4,1,0) -> 1 | BB6: =Table1[[#This Row],[Mortage Left]]/Table1[[#This Row],[Value of House]] -> 0.51436845 | BC6: =IF(BB6<$BD$4,1,0) -> 0 | BG6: =IF(Table1[[#This Row],[County]]="Cumbria",Table1[[#This Row],[income]],0) -> 0 | BH6: =IF(Table1[[#This Row],[County]]="Cheshire",Table1[[#This Row],[income]],0) -> 0 | BI6: =IF(Table1[[#This Row],[County]]="Bristol",Table1[[#This Row],[income]],0) -> 0 | BJ6: =IF(Table1[[#This Row],[County]]="Surrey",Table1[[#This Row],[income]],0) -> 0 | BK6: =IF(Table1[[#This Row],[County]]="Norfolk",Table1[[#This Row],[income]],0) -> 0 | BL6: =IF(Table1[[#This Row],[County]]="Lincolnshire",Table1[[#This Row],[income]],0) -> 0 | BM6: =IF(Table1[[#This Row],[County]]="Somerset",Table1[[#This Row],[income]],0) -> 0 | BN6: =IF(Table1[[#This Row],[County]]="Cambridgeshire",Table1[[#This Row],[income]],0) -> 0 | BO6: =IF(Table1[[#This Row],[County]]="South Yorkshire",Table1[[#This Row],[income]],0) -> 0 | BP6: =IF(Table1[[#This Row],[County]]="Greater London",Table1[[#This Row],[income]],0) -> 0 | BQ6: =IF(Table1[[#This Row],[County]]="Hampshire",Table1[[#This Row],[income]],0) -> 0 | BR6: =IF(Table1[[#This Row],[County]]="Gloucestershire",Table1[[#This Row],[income]],0) -> 0 | BS6: =IF(Table1[[#This Row],[County]]="West Sussex",Table1[[#This Row],[income]],0) -> 0 | BT6: =IF(Table1[[#This Row],[County]]="Devon",Table1[[#This Row],[income]],0) -> 0 | BU6: =IF(Table1[[#This Row],[County]]="Berkshire",Table1[[#This Row],[income]],0) -> 0 | BV6: =IF(Table1[[#This Row],[County]]="Staffordshire",Table1[[#This Row],[income]],0) -> 0 | BW6: =IF(Table1[[#This Row],[County]]="Leicestershire",Table1[[#This Row],[income]],0) -> 0 | BX6: =IF(Table1[[#This Row],[County]]="Cornwall",Table1[[#This Row],[income]],0) -> 0 | BY6: =IF(Table1[[#This Row],[County]]="Isle of Wight",Table1[[#This Row],[income]],0) -> 0 | BZ6: =IF(Table1[[#This Row],[County]]="Surrey",Table1[[#This Row],[income]],0) -> 0 | CA6: =IF(Table1[[#This Row],[County]]="Derbyshire",Table1[[#This Row],[income]],0) -> 0 | CB6: =IF(Table1[[#This Row],[County]]="City of London",Table1[[#This Row],[income]],0) -> 0 | CC6: =IF(Table1[[#This Row],[County]]="Bedfordshire",Table1[[#This Row],[income]],0) -> 0 | CD6: =IF(Table1[[#This Row],[County]]="County Durham",Table1[[#This Row],[income]],0) -> 0 | CE6: =IF(Table1[[#This Row],[County]]="East Riding of Yorkshire",Table1[[#This Row],[income]],0) -> 0 | CF6: =IF(Table1[[#This Row],[County]]="West Yorkshire",Table1[[#This Row],[income]],0) -> 0 | CG6: =IF(Table1[[#This Row],[County]]="Essex",Table1[[#This Row],[income]],0) -> 0 | CH6: =IF(Table1[[#This Row],[County]]="East Sussex",Table1[[#This Row],[income]],0) -> 0 | CI6: =IF(Table1[[#This Row],[County]]="Greater Manchester",Table1[[#This Row],[income]],0) -> 0 | CJ6: =IF(Table1[[#This Row],[County]]="Hertfordshire",Table1[[#This Row],[income]],0) -> 0 | CK6: =IF(Table1[[#This Row],[County]]="Herefordshire",Table1[[#This Row],[income]],0) -> 0 | CL6: =IF(Table1[[#This Row],[County]]="Lancashire",Table1[[#This Row],[income]],0) -> 81268 | CM6: =IF(Table1[[#This Row],[County]]="Merseyside",Table1[[#This Row],[income]],0) -> 0 | CN6: =IF(Table1[[#This Row],[County]]="Northamptonshire",Table1[[#This Row],[income]],0) -> 0 | CO6: =IF(Table1[[#This Row],[County]]="Northumberland",Table1[[#This Row],[income]],0) -> 0 | CP6: =IF(Table1[[#This Row],[County]]="Wiltshire",Table1[[#This Row],[income]],0) -> 0 | CQ6: =IF(Table1[[#This Row],[County]]="West Midlands",Table1[[#This Row],[income]],0) -> 0 | CR6: =IF(Table1[[#This Row],[County]]="Warwickshire",Table1[[#This Row],[income]],0) -> 0 | CS6: =IF(Table1[[#This Row],[County]]="Tyne and Wear",Table1[[#This Row],[income]],0) -> 0 | CT6: =IF(Table1[[#This Row],[County]]="Worcestershire",Table1[[#This Row],[income]],0) -> 0 | CU6: =IF(Table1[[#This Row],[County]]="Rutland",Table1[[#This Row],[income]],0) -> 0 | CV6: =IF(Table1[[#This Row],[County]]="Shropshire",Table1[[#This Row],[income]],0) -> 0 | CW6: =IF(Table1[[#This Row],[County]]="Dorset",Table1[[#This Row],[income]],0) -> 0 | CX6: =IF(Table1[[#This Row],[County]]="Buckinghamshire",Table1[[#This Row],[income]],0) -> 0 | CY6: =IF(Table1[[#This Row],[County]]="Suffolk",Table1[[#This Row],[income]],0) -> 0 | CZ6: =IF(Table1[[#This Row],[County]]="North Yorkshire",Table1[[#This Row],[income]],0) -> 0 | DA6: =IF(Table1[[#This Row],[County]]="Kent",Table1[[#This Row],[income]],0) -> 0 | DB6: =IF(Table1[[#This Row],[County]]="Derbyshire",Table1[[#This Row],[income]],0) -> 0 | DD6: =IF(Table1[[#This Row],[Column1]]="Health",Table1[[#This Row],[income]],0) -> 0 | DE6: =IF(Table1[[#This Row],[Column1]]="Agriculture",Table1[[#This Row],[income]],0) -> 0 | DF6: =IF(Table1[[#This Row],[Column1]]="Technology",Table1[[#This Row],[income]],0) -> 0 | DG6: =IF(Table1[[#This Row],[Column1]]="Social Service",Table1[[#This Row],[income]],0) -> 0 | DH6: =IF(Table1[[#This Row],[Column1]]="Education",Table1[[#This Row],[income]],0) -> 81268 | DI6: =IF(Table1[[#This Row],[Column1]]="Construction",Table1[[#This Row],[income]],0) -> 0 | DK6: =IF(Table1[[#This Row],[Value of Debts]]>Table1[[#This Row],[income]],1,0) -> 1 | DP6: =IF(Table1[[#This Row],[Net Worth (£)]]>$DS$5,C6,0) -> 0
A7: =RANDBETWEEN(1,2) -> 2 | B7: =IF(A7=1, "men", "women") -> women | C7: =RANDBETWEEN(25,50) -> 47 | D7: =RANDBETWEEN(1,6) -> 2 | E7: =VLOOKUP(D7,$W$5:$X$10,2) -> Construction | F7: =RANDBETWEEN(1,5) -> 4 | G7: =VLOOKUP(F7,$Y$5:$Z$9,2) -> Technical | H7: =RANDBETWEEN(0,4) -> 3 | I7: =RANDBETWEEN(1,3) -> 2 | J7: =RANDBETWEEN(30000,100000) -> 65006 | K7: =RANDBETWEEN(1,48) -> 45 | L7: =VLOOKUP(K7,$AA$5:$AB$52,2) -> West Sussex | M7: =J7*(RANDBETWEEN(2,5)) -> 195018 | N7: =RAND()*M7 -> 132368.15 | O7: =I7*RAND()*J7 -> 68194.788 | P7: =RANDBETWEEN(0,O7) -> 29590 | Q7: =RAND()*J7*2 -> 76660.811 | R7: =RAND()*J7*1.5 -> 10105.052 | S7: =J7+R7+O7 -> 143305.84 | T7: =N7+P7+Q7 -> 238618.96 | U7: =S7-T7 -> -95313.119 | W7: 3 | X7: Education | Y7: 3 | Z7: University | AA7: 3 | AB7: Bristol | AC7: =IF(Table1[[#This Row],[gender]]="men",1,0) -> 0 | AD7: =IF(Table1[[#This Row],[gender]]="women",1,0) -> 1 | AJ7: =IF(Table1[[#This Row],[Column1]]="Health",1,0) -> 0 | AK7: =IF(Table1[[#This Row],[Column1]]="Construction",1,0) -> 1 | AL7: =IF(Table1[[#This Row],[Column1]]="Technology",1,0) -> 0 | AM7: =IF(Table1[[#This Row],[Column1]]="Education",1,0) -> 0 | AN7: =IF(Table1[[#This Row],[Column1]]="Agriculture",1,0) -> 0 | AO7: =IF(Table1[[#This Row],[Column1]]="Social Service", 1, 0) -> 0 | AV7: =(O8/I8) -> 10340.289 | AX7: =IF(Table1[[#This Row],[Value of Debts]]>$AY$4,1,0) -> 1 | BB7: =Table1[[#This Row],[Mortage Left]]/Table1[[#This Row],[Value of House]] -> 0.67874836 | BC7: =IF(BB7<$BD$4,1,0) -> 0 | BG7: =IF(Table1[[#This Row],[County]]="Cumbria",Table1[[#This Row],[income]],0) -> 0 | BH7: =IF(Table1[[#This Row],[County]]="Cheshire",Table1[[#This Row],[income]],0) -> 0 | BI7: =IF(Table1[[#This Row],[County]]="Bristol",Table1[[#This Row],[income]],0) -> 0 | BJ7: =IF(Table1[[#This Row],[County]]="Surrey",Table1[[#This Row],[income]],0) -> 0 | BK7: =IF(Table1[[#This Row],[County]]="Norfolk",Table1[[#This Row],[income]],0) -> 0 | BL7: =IF(Table1[[#This Row],[County]]="Lincolnshire",Table1[[#This Row],[income]],0) -> 0 | BM7: =IF(Table1[[#This Row],[County]]="Somerset",Table1[[#This Row],[income]],0) -> 0 | BN7: =IF(Table1[[#This Row],[County]]="Cambridgeshire",Table1[[#This Row],[income]],0) -> 0 | BO7: =IF(Table1[[#This Row],[County]]="South Yorkshire",Table1[[#This Row],[income]],0) -> 0 | BP7: =IF(Table1[[#This Row],[County]]="Greater London",Table1[[#This Row],[income]],0) -> 0 | BQ7: =IF(Table1[[#This Row],[County]]="Hampshire",Table1[[#This Row],[income]],0) -> 0 | BR7: =IF(Table1[[#This Row],[County]]="Gloucestershire",Table1[[#This Row],[income]],0) -> 0 | BS7: =IF(Table1[[#This Row],[County]]="West Sussex",Table1[[#This Row],[income]],0) -> 65006 | BT7: =IF(Table1[[#This Row],[County]]="Devon",Table1[[#This Row],[income]],0) -> 0 | BU7: =IF(Table1[[#This Row],[County]]="Berkshire",Table1[[#This Row],[income]],0) -> 0 | BV7: =IF(Table1[[#This Row],[County]]="Staffordshire",Table1[[#This Row],[income]],0) -> 0 | BW7: =IF(Table1[[#This Row],[County]]="Leicestershire",Table1[[#This Row],[income]],0) -> 0 | BX7: =IF(Table1[[#This Row],[County]]="Cornwall",Table1[[#This Row],[income]],0) -> 0 | BY7: =IF(Table1[[#This Row],[County]]="Isle of Wight",Table1[[#This Row],[income]],0) -> 0 | BZ7: =IF(Table1[[#This Row],[County]]="Surrey",Table1[[#This Row],[income]],0) -> 0 | CA7: =IF(Table1[[#This Row],[County]]="Derbyshire",Table1[[#This Row],[income]],0) -> 0 | CB7: =IF(Table1[[#This Row],[County]]="City of London",Table1[[#This Row],[income]],0) -> 0 | CC7: =IF(Table1[[#This Row],[County]]="Bedfordshire",Table1[[#This Row],[income]],0) -> 0 | CD7: =IF(Table1[[#This Row],[County]]="County Durham",Table1[[#This Row],[income]],0) -> 0 | CE7: =IF(Table1[[#This Row],[County]]="East Riding of Yorkshire",Table1[[#This Row],[income]],0) -> 0 | CF7: =IF(Table1[[#This Row],[County]]="West Yorkshire",Table1[[#This Row],[income]],0) -> 0 | CG7: =IF(Table1[[#This Row],[County]]="Essex",Table1[[#This Row],[income]],0) -> 0 | CH7: =IF(Table1[[#This Row],[County]]="East Sussex",Table1[[#This Row],[income]],0) -> 0 | CI7: =IF(Table1[[#This Row],[County]]="Greater Manchester",Table1[[#This Row],[income]],0) -> 0 | CJ7: =IF(Table1[[#This Row],[County]]="Hertfordshire",Table1[[#This Row],[income]],0) -> 0 | CK7: =IF(Table1[[#This Row],[County]]="Herefordshire",Table1[[#This Row],[income]],0) -> 0 | CL7: =IF(Table1[[#This Row],[County]]="Lancashire",Table1[[#This Row],[income]],0) -> 0 | CM7: =IF(Table1[[#This Row],[County]]="Merseyside",Table1[[#This Row],[income]],0) -> 0 | CN7: =IF(Table1[[#This Row],[County]]="Northamptonshire",Table1[[#This Row],[income]],0) -> 0 | CO7: =IF(Table1[[#This Row],[County]]="Northumberland",Table1[[#This Row],[income]],0) -> 0 | CP7: =IF(Table1[[#This Row],[County]]="Wiltshire",Table1[[#This Row],[income]],0) -> 0 | CQ7: =IF(Table1[[#This Row],[County]]="West Midlands",Table1[[#This Row],[income]],0) -> 0 | CR7: =IF(Table1[[#This Row],[County]]="Warwickshire",Table1[[#This Row],[income]],0) -> 0 | CS7: =IF(Table1[[#This Row],[County]]="Tyne and Wear",Table1[[#This Row],[income]],0) -> 0 | CT7: =IF(Table1[[#This Row],[County]]="Worcestershire",Table1[[#This Row],[income]],0) -> 0 | CU7: =IF(Table1[[#This Row],[County]]="Rutland",Table1[[#This Row],[income]],0) -> 0 | CV7: =IF(Table1[[#This Row],[County]]="Shropshire",Table1[[#This Row],[income]],0) -> 0 | CW7: =IF(Table1[[#This Row],[County]]="Dorset",Table1[[#This Row],[income]],0) -> 0 | CX7: =IF(Table1[[#This Row],[County]]="Buckinghamshire",Table1[[#This Row],[income]],0) -> 0 | CY7: =IF(Table1[[#This Row],[County]]="Suffolk",Table1[[#This Row],[income]],0) -> 0 | CZ7: =IF(Table1[[#This Row],[County]]="North Yorkshire",Table1[[#This Row],[income]],0) -> 0 | DA7: =IF(Table1[[#This Row],[County]]="Kent",Table1[[#This Row],[income]],0) -> 0 | DB7: =IF(Table1[[#This Row],[County]]="Derbyshire",Table1[[#This Row],[income]],0) -> 0 | DD7: =IF(Table1[[#This Row],[Column1]]="Health",Table1[[#This Row],[income]],0) -> 0 | DE7: =IF(Table1[[#This Row],[Column1]]="Agriculture",Table1[[#This Row],[income]],0) -> 0 | DF7: =IF(Table1[[#This Row],[Column1]]="Technology",Table1[[#This Row],[income]],0) -> 0 | DG7: =IF(Table1[[#This Row],[Column1]]="Social Service",Table1[[#This Row],[income]],0) -> 0 | DH7: =IF(Table1[[#This Row],[Column1]]="Education",Table1[[#This Row],[income]],0) -> 0 | DI7: =IF(Table1[[#This Row],[Column1]]="Construction",Table1[[#This Row],[income]],0) -> 65006 | DK7: =IF(Table1[[#This Row],[Value of Debts]]>Table1[[#This Row],[income]],1,0) -> 1 | DP7: =IF(Table1[[#This Row],[Net Worth (£)]]>$DS$5,C7,0) -> 0
A8: =RANDBETWEEN(1,2) -> 2 | B8: =IF(A8=1, "men", "women") -> women | C8: =RANDBETWEEN(25,50) -> 25 | D8: =RANDBETWEEN(1,6) -> 6 | E8: =VLOOKUP(D8,$W$5:$X$10,2) -> Agriculture | F8: =RANDBETWEEN(1,5) -> 4 | G8: =VLOOKUP(F8,$Y$5:$Z$9,2) -> Technical | H8: =RANDBETWEEN(0,4) -> 0 | I8: =RANDBETWEEN(1,3) -> 1 | J8: =RANDBETWEEN(30000,100000) -> 48868 | K8: =RANDBETWEEN(1,48) -> 2 | L8: =VLOOKUP(K8,$AA$5:$AB$52,2) -> Berkshire | M8: =J8*(RANDBETWEEN(2,5)) -> 146604 | N8: =RAND()*M8 -> 5095.415 | O8: =I8*RAND()*J8 -> 10340.289 | P8: =RANDBETWEEN(0,O8) -> 2195 | Q8: =RAND()*J8*2 -> 2978.7983 | R8: =RAND()*J8*1.5 -> 36638.203 | S8: =J8+R8+O8 -> 95846.492 | T8: =N8+P8+Q8 -> 10269.213 | U8: =S8-T8 -> 85577.278 | W8: 4 | X8: Technology | Y8: 4 | Z8: Technical | AA8: 4 | AB8: Buckinghamshire | AC8: =IF(Table1[[#This Row],[gender]]="men",1,0) -> 0 | AD8: =IF(Table1[[#This Row],[gender]]="women",1,0) -> 1 | AJ8: =IF(Table1[[#This Row],[Column1]]="Health",1,0) -> 0 | AK8: =IF(Table1[[#This Row],[Column1]]="Construction",1,0) -> 0 | AL8: =IF(Table1[[#This Row],[Column1]]="Technology",1,0) -> 0 | AM8: =IF(Table1[[#This Row],[Column1]]="Education",1,0) -> 0 | AN8: =IF(Table1[[#This Row],[Column1]]="Agriculture",1,0) -> 1 | AO8: =IF(Table1[[#This Row],[Column1]]="Social Service", 1, 0) -> 0 | AV8: =(O9/I9) -> 39644.496 | AX8: =IF(Table1[[#This Row],[Value of Debts]]>$AY$4,1,0) -> 0 | BB8: =Table1[[#This Row],[Mortage Left]]/Table1[[#This Row],[Value of House]] -> 0.034756316 | BC8: =IF(BB8<$BD$4,1,0) -> 1 | BG8: =IF(Table1[[#This Row],[County]]="Cumbria",Table1[[#This Row],[income]],0) -> 0 | BH8: =IF(Table1[[#This Row],[County]]="Cheshire",Table1[[#This Row],[income]],0) -> 0 | BI8: =IF(Table1[[#This Row],[County]]="Bristol",Table1[[#This Row],[income]],0) -> 0 | BJ8: =IF(Table1[[#This Row],[County]]="Surrey",Table1[[#This Row],[income]],0) -> 0 | BK8: =IF(Table1[[#This Row],[County]]="Norfolk",Table1[[#This Row],[income]],0) -> 0 | BL8: =IF(Table1[[#This Row],[County]]="Lincolnshire",Table1[[#This Row],[income]],0) -> 0 | BM8: =IF(Table1[[#This Row],[County]]="Somerset",Table1[[#This Row],[income]],0) -> 0 | BN8: =IF(Table1[[#This Row],[County]]="Cambridgeshire",Table1[[#This Row],[income]],0) -> 0 | BO8: =IF(Table1[[#This Row],[County]]="South Yorkshire",Table1[[#This Row],[income]],0) -> 0 | BP8: =IF(Table1[[#This Row],[County]]="Greater London",Table1[[#This Row],[income]],0) -> 0 | BQ8: =IF(Table1[[#This Row],[County]]="Hampshire",Table1[[#This Row],[income]],0) -> 0 | BR8: =IF(Table1[[#This Row],[County]]="Gloucestershire",Table1[[#This Row],[income]],0) -> 0 | BS8: =IF(Table1[[#This Row],[County]]="West Sussex",Table1[[#This Row],[income]],0) -> 0 | BT8: =IF(Table1[[#This Row],[County]]="Devon",Table1[[#This Row],[income]],0) -> 0 | BU8: =IF(Table1[[#This Row],[County]]="Berkshire",Table1[[#This Row],[income]],0) -> 48868 | BV8: =IF(Table1[[#This Row],[County]]="Staffordshire",Table1[[#This Row],[income]],0) -> 0 | BW8: =IF(Table1[[#This Row],[County]]="Leicestershire",Table1[[#This Row],[income]],0) -> 0 | BX8: =IF(Table1[[#This Row],[County]]="Cornwall",Table1[[#This Row],[income]],0) -> 0 | BY8: =IF(Table1[[#This Row],[County]]="Isle of Wight",Table1[[#This Row],[income]],0) -> 0 | BZ8: =IF(Table1[[#This Row],[County]]="Surrey",Table1[[#This Row],[income]],0) -> 0 | CA8: =IF(Table1[[#This Row],[County]]="Derbyshire",Table1[[#This Row],[income]],0) -> 0 | CB8: =IF(Table1[[#This Row],[County]]="City of London",Table1[[#This Row],[income]],0) -> 0 | CC8: =IF(Table1[[#This Row],[County]]="Bedfordshire",Table1[[#This Row],[income]],0) -> 0 | CD8: =IF(Table1[[#This Row],[County]]="County Durham",Table1[[#This Row],[income]],0) -> 0 | CE8: =IF(Table1[[#This Row],[County]]="East Riding of Yorkshire",Table1[[#This Row],[income]],0) -> 0 | CF8: =IF(Table1[[#This Row],[County]]="West Yorkshire",Table1[[#This Row],[income]],0) -> 0 | CG8: =IF(Table1[[#This Row],[County]]="Essex",Table1[[#This Row],[income]],0) -> 0 | CH8: =IF(Table1[[#This Row],[County]]="East Sussex",Table1[[#This Row],[income]],0) -> 0 | CI8: =IF(Table1[[#This Row],[County]]="Greater Manchester",Table1[[#This Row],[income]],0) -> 0 | CJ8: =IF(Table1[[#This Row],[County]]="Hertfordshire",Table1[[#This Row],[income]],0) -> 0 | CK8: =IF(Table1[[#This Row],[County]]="Herefordshire",Table1[[#This Row],[income]],0) -> 0 | CL8: =IF(Table1[[#This Row],[County]]="Lancashire",Table1[[#This Row],[income]],0) -> 0 | CM8: =IF(Table1[[#This Row],[County]]="Merseyside",Table1[[#This Row],[income]],0) -> 0 | CN8: =IF(Table1[[#This Row],[County]]="Northamptonshire",Table1[[#This Row],[income]],0) -> 0 | CO8: =IF(Table1[[#This Row],[County]]="Northumberland",Table1[[#This Row],[income]],0) -> 0 | CP8: =IF(Table1[[#This Row],[County]]="Wiltshire",Table1[[#This Row],[income]],0) -> 0 | CQ8: =IF(Table1[[#This Row],[County]]="West Midlands",Table1[[#This Row],[income]],0) -> 0 | CR8: =IF(Table1[[#This Row],[County]]="Warwickshire",Table1[[#This Row],[income]],0) -> 0 | CS8: =IF(Table1[[#This Row],[County]]="Tyne and Wear",Table1[[#This Row],[income]],0) -> 0 | CT8: =IF(Table1[[#This Row],[County]]="Worcestershire",Table1[[#This Row],[income]],0) -> 0 | CU8: =IF(Table1[[#This Row],[County]]="Rutland",Table1[[#This Row],[income]],0) -> 0 | CV8: =IF(Table1[[#This Row],[County]]="Shropshire",Table1[[#This Row],[income]],0) -> 0 | CW8: =IF(Table1[[#This Row],[County]]="Dorset",Table1[[#This Row],[income]],0) -> 0 | CX8: =IF(Table1[[#This Row],[County]]="Buckinghamshire",Table1[[#This Row],[income]],0) -> 0 | CY8: =IF(Table1[[#This Row],[County]]="Suffolk",Table1[[#This Row],[income]],0) -> 0 | CZ8: =IF(Table1[[#This Row],[County]]="North Yorkshire",Table1[[#This Row],[income]],0) -> 0 | DA8: =IF(Table1[[#This Row],[County]]="Kent",Table1[[#This Row],[income]],0) -> 0 | DB8: =IF(Table1[[#This Row],[County]]="Derbyshire",Table1[[#This Row],[income]],0) -> 0 | DD8: =IF(Table1[[#This Row],[Column1]]="Health",Table1[[#This Row],[income]],0) -> 0 | DE8: =IF(Table1[[#This Row],[Column1]]="Agriculture",Table1[[#This Row],[income]],0) -> 48868 | DF8: =IF(Table1[[#This Row],[Column1]]="Technology",Table1[[#This Row],[income]],0) -> 0 | DG8: =IF(Table1[[#This Row],[Column1]]="Social Service",Table1[[#This Row],[income]],0) -> 0 | DH8: =IF(Table1[[#This Row],[Column1]]="Education",Table1[[#This Row],[income]],0) -> 0 | DI8: =IF(Table1[[#This Row],[Column1]]="Construction",Table1[[#This Row],[income]],0) -> 0 | DK8: =IF(Table1[[#This Row],[Value of Debts]]>Table1[[#This Row],[income]],1,0) -> 0 | DP8: =IF(Table1[[#This Row],[Net Worth (£)]]>$DS$5,C8,0) -> 25
A9: =RANDBETWEEN(1,2) -> 1 | B9: =IF(A9=1, "men", "women") -> men | C9: =RANDBETWEEN(25,50) -> 44 | D9: =RANDBETWEEN(1,6) -> 1 | E9: =VLOOKUP(D9,$W$5:$X$10,2) -> Health | F9: =RANDBETWEEN(1,5) -> 1 | G9: =VLOOKUP(F9,$Y$5:$Z$9,2) -> High School | H9: =RANDBETWEEN(0,4) -> 4 | I9: =RANDBETWEEN(1,3) -> 3 | J9: =RANDBETWEEN(30000,100000) -> 57830 | K9: =RANDBETWEEN(1,48) -> 45 | L9: =VLOOKUP(K9,$AA$5:$AB$52,2) -> West Sussex | M9: =J9*(RANDBETWEEN(2,5)) -> 289150 | N9: =RAND()*M9 -> 57797.404 | O9: =I9*RAND()*J9 -> 118933.49 | P9: =RANDBETWEEN(0,O9) -> 36395 | Q9: =RAND()*J9*2 -> 95846.65 | R9: =RAND()*J9*1.5 -> 39381.92 | S9: =J9+R9+O9 -> 216145.41 | T9: =N9+P9+Q9 -> 190039.05 | U9: =S9-T9 -> 26106.354 | W9: 5 | X9: Social Service | Y9: 5 | Z9: Other | AA9: 5 | AB9: Cambridgeshire | AC9: =IF(Table1[[#This Row],[gender]]="men",1,0) -> 1 | AD9: =IF(Table1[[#This Row],[gender]]="women",1,0) -> 0 | AJ9: =IF(Table1[[#This Row],[Column1]]="Health",1,0) -> 1 | AK9: =IF(Table1[[#This Row],[Column1]]="Construction",1,0) -> 0 | AL9: =IF(Table1[[#This Row],[Column1]]="Technology",1,0) -> 0 | AM9: =IF(Table1[[#This Row],[Column1]]="Education",1,0) -> 0 | AN9: =IF(Table1[[#This Row],[Column1]]="Agriculture",1,0) -> 0 | AO9: =IF(Table1[[#This Row],[Column1]]="Social Service", 1, 0) -> 0 | AV9: =(O10/I10) -> 30421.163 | AX9: =IF(Table1[[#This Row],[Value of Debts]]>$AY$4,1,0) -> 1 | BB9: =Table1[[#This Row],[Mortage Left]]/Table1[[#This Row],[Value of House]] -> 0.19988727 | BC9: =IF(BB9<$BD$4,1,0) -> 1 | BG9: =IF(Table1[[#This Row],[County]]="Cumbria",Table1[[#This Row],[income]],0) -> 0 | BH9: =IF(Table1[[#This Row],[County]]="Cheshire",Table1[[#This Row],[income]],0) -> 0 | BI9: =IF(Table1[[#This Row],[County]]="Bristol",Table1[[#This Row],[income]],0) -> 0 | BJ9: =IF(Table1[[#This Row],[County]]="Surrey",Table1[[#This Row],[income]],0) -> 0 | BK9: =IF(Table1[[#This Row],[County]]="Norfolk",Table1[[#This Row],[income]],0) -> 0 | BL9: =IF(Table1[[#This Row],[County]]="Lincolnshire",Table1[[#This Row],[income]],0) -> 0 | BM9: =IF(Table1[[#This Row],[County]]="Somerset",Table1[[#This Row],[income]],0) -> 0 | BN9: =IF(Table1[[#This Row],[County]]="Cambridgeshire",Table1[[#This Row],[income]],0) -> 0 | BO9: =IF(Table1[[#This Row],[County]]="South Yorkshire",Table1[[#This Row],[income]],0) -> 0 | BP9: =IF(Table1[[#This Row],[County]]="Greater London",Table1[[#This Row],[income]],0) -> 0 | BQ9: =IF(Table1[[#This Row],[County]]="Hampshire",Table1[[#This Row],[income]],0) -> 0 | BR9: =IF(Table1[[#This Row],[County]]="Gloucestershire",Table1[[#This Row],[income]],0) -> 0 | BS9: =IF(Table1[[#This Row],[County]]="West Sussex",Table1[[#This Row],[income]],0) -> 57830 | BT9: =IF(Table1[[#This Row],[County]]="Devon",Table1[[#This Row],[income]],0) -> 0 | BU9: =IF(Table1[[#This Row],[County]]="Berkshire",Table1[[#This Row],[income]],0) -> 0 | BV9: =IF(Table1[[#This Row],[County]]="Staffordshire",Table1[[#This Row],[income]],0) -> 0 | BW9: =IF(Table1[[#This Row],[County]]="Leicestershire",Table1[[#This Row],[income]],0) -> 0 | BX9: =IF(Table1[[#This Row],[County]]="Cornwall",Table1[[#This Row],[income]],0) -> 0 | BY9: =IF(Table1[[#This Row],[County]]="Isle of Wight",Table1[[#This Row],[income]],0) -> 0 | BZ9: =IF(Table1[[#This Row],[County]]="Surrey",Table1[[#This Row],[income]],0) -> 0 | CA9: =IF(Table1[[#This Row],[County]]="Derbyshire",Table1[[#This Row],[income]],0) -> 0 | CB9: =IF(Table1[[#This Row],[County]]="City of London",Table1[[#This Row],[income]],0) -> 0 | CC9: =IF(Table1[[#This Row],[County]]="Bedfordshire",Table1[[#This Row],[income]],0) -> 0 | CD9: =IF(Table1[[#This Row],[County]]="County Durham",Table1[[#This Row],[income]],0) -> 0 | CE9: =IF(Table1[[#This Row],[County]]="East Riding of Yorkshire",Table1[[#This Row],[income]],0) -> 0 | CF9: =IF(Table1[[#This Row],[County]]="West Yorkshire",Table1[[#This Row],[income]],0) -> 0 | CG9: =IF(Table1[[#This Row],[County]]="Essex",Table1[[#This Row],[income]],0) -> 0 | CH9: =IF(Table1[[#This Row],[County]]="East Sussex",Table1[[#This Row],[income]],0) -> 0 | CI9: =IF(Table1[[#This Row],[County]]="Greater Manchester",Table1[[#This Row],[income]],0) -> 0 | CJ9: =IF(Table1[[#This Row],[County]]="Hertfordshire",Table1[[#This Row],[income]],0) -> 0 | CK9: =IF(Table1[[#This Row],[County]]="Herefordshire",Table1[[#This Row],[income]],0) -> 0 | CL9: =IF(Table1[[#This Row],[County]]="Lancashire",Table1[[#This Row],[income]],0) -> 0 | CM9: =IF(Table1[[#This Row],[County]]="Merseyside",Table1[[#This Row],[income]],0) -> 0 | CN9: =IF(Table1[[#This Row],[County]]="Northamptonshire",Table1[[#This Row],[income]],0) -> 0 | CO9: =IF(Table1[[#This Row],[County]]="Northumberland",Table1[[#This Row],[income]],0) -> 0 | CP9: =IF(Table1[[#This Row],[County]]="Wiltshire",Table1[[#This Row],[income]],0) -> 0 | CQ9: =IF(Table1[[#This Row],[County]]="West Midlands",Table1[[#This Row],[income]],0) -> 0 | CR9: =IF(Table1[[#This Row],[County]]="Warwickshire",Table1[[#This Row],[income]],0) -> 0 | CS9: =IF(Table1[[#This Row],[County]]="Tyne and Wear",Table1[[#This Row],[income]],0) -> 0 | CT9: =IF(Table1[[#This Row],[County]]="Worcestershire",Table1[[#This Row],[income]],0) -> 0 | CU9: =IF(Table1[[#This Row],[County]]="Rutland",Table1[[#This Row],[income]],0) -> 0 | CV9: =IF(Table1[[#This Row],[County]]="Shropshire",Table1[[#This Row],[income]],0) -> 0 | CW9: =IF(Table1[[#This Row],[County]]="Dorset",Table1[[#This Row],[income]],0) -> 0 | CX9: =IF(Table1[[#This Row],[County]]="Buckinghamshire",Table1[[#This Row],[income]],0) -> 0 | CY9: =IF(Table1[[#This Row],[County]]="Suffolk",Table1[[#This Row],[income]],0) -> 0 | CZ9: =IF(Table1[[#This Row],[County]]="North Yorkshire",Table1[[#This Row],[income]],0) -> 0 | DA9: =IF(Table1[[#This Row],[County]]="Kent",Table1[[#This Row],[income]],0) -> 0 | DB9: =IF(Table1[[#This Row],[County]]="Derbyshire",Table1[[#This Row],[income]],0) -> 0 | DD9: =IF(Table1[[#This Row],[Column1]]="Health",Table1[[#This Row],[income]],0) -> 57830 | DE9: =IF(Table1[[#This Row],[Column1]]="Agriculture",Table1[[#This Row],[income]],0) -> 0 | DF9: =IF(Table1[[#This Row],[Column1]]="Technology",Table1[[#This Row],[income]],0) -> 0 | DG9: =IF(Table1[[#This Row],[Column1]]="Social Service",Table1[[#This Row],[income]],0) -> 0 | DH9: =IF(Table1[[#This Row],[Column1]]="Education",Table1[[#This Row],[income]],0) -> 0 | DI9: =IF(Table1[[#This Row],[Column1]]="Construction",Table1[[#This Row],[income]],0) -> 0 | DK9: =IF(Table1[[#This Row],[Value of Debts]]>Table1[[#This Row],[income]],1,0) -> 1 | DP9: =IF(Table1[[#This Row],[Net Worth (£)]]>$DS$5,C9,0) -> 0
A10: =RANDBETWEEN(1,2) -> 1 | B10: =IF(A10=1, "men", "women") -> men | C10: =RANDBETWEEN(25,50) -> 50 | D10: =RANDBETWEEN(1,6) -> 6 | E10: =VLOOKUP(D10,$W$5:$X$10,2) -> Agriculture | F10: =RANDBETWEEN(1,5) -> 5 | G10: =VLOOKUP(F10,$Y$5:$Z$9,2) -> Other | H10: =RANDBETWEEN(0,4) -> 1 | I10: =RANDBETWEEN(1,3) -> 3 | J10: =RANDBETWEEN(30000,100000) -> 79805 | K10: =RANDBETWEEN(1,48) -> 44 | L10: =VLOOKUP(K10,$AA$5:$AB$52,2) -> West Midlands | M10: =J10*(RANDBETWEEN(2,5)) -> 159610 | N10: =RAND()*M10 -> 123365.78 | O10: =I10*RAND()*J10 -> 91263.489 | P10: =RANDBETWEEN(0,O10) -> 6964 | Q10: =RAND()*J10*2 -> 8009.7784 | R10: =RAND()*J10*1.5 -> 62221.675 | S10: =J10+R10+O10 -> 233290.16 | T10: =N10+P10+Q10 -> 138339.55 | U10: =S10-T10 -> 94950.61 | W10: 6 | X10: Agriculture | AA10: 6 | AB10: Cheshire | AC10: =IF(Table1[[#This Row],[gender]]="men",1,0) -> 1 | AD10: =IF(Table1[[#This Row],[gender]]="women",1,0) -> 0 | AJ10: =IF(Table1[[#This Row],[Column1]]="Health",1,0) -> 0 | AK10: =IF(Table1[[#This Row],[Column1]]="Construction",1,0) -> 0 | AL10: =IF(Table1[[#This Row],[Column1]]="Technology",1,0) -> 0 | AM10: =IF(Table1[[#This Row],[Column1]]="Education",1,0) -> 0 | AN10: =IF(Table1[[#This Row],[Column1]]="Agriculture",1,0) -> 1 | AO10: =IF(Table1[[#This Row],[Column1]]="Social Service", 1, 0) -> 0 | AV10: =(O11/I11) -> 4252.9765 | AX10: =IF(Table1[[#This Row],[Value of Debts]]>$AY$4,1,0) -> 1 | BB10: =Table1[[#This Row],[Mortage Left]]/Table1[[#This Row],[Value of House]] -> 0.77292009 | BC10: =IF(BB10<$BD$4,1,0) -> 0 | BG10: =IF(Table1[[#This Row],[County]]="Cumbria",Table1[[#This Row],[income]],0) -> 0 | BH10: =IF(Table1[[#This Row],[County]]="Cheshire",Table1[[#This Row],[income]],0) -> 0 | BI10: =IF(Table1[[#This Row],[County]]="Bristol",Table1[[#This Row],[income]],0) -> 0 | BJ10: =IF(Table1[[#This Row],[County]]="Surrey",Table1[[#This Row],[income]],0) -> 0 | BK10: =IF(Table1[[#This Row],[County]]="Norfolk",Table1[[#This Row],[income]],0) -> 0 | BL10: =IF(Table1[[#This Row],[County]]="Lincolnshire",Table1[[#This Row],[income]],0) -> 0 | BM10: =IF(Table1[[#This Row],[County]]="Somerset",Table1[[#This Row],[income]],0) -> 0 | BN10: =IF(Table1[[#This Row],[County]]="Cambridgeshire",Table1[[#This Row],[income]],0) -> 0 | BO10: =IF(Table1[[#This Row],[County]]="South Yorkshire",Table1[[#This Row],[income]],0) -> 0 | BP10: =IF(Table1[[#This Row],[County]]="Greater London",Table1[[#This Row],[income]],0) -> 0 | BQ10: =IF(Table1[[#This Row],[County]]="Hampshire",Table1[[#This Row],[income]],0) -> 0 | BR10: =IF(Table1[[#This Row],[County]]="Gloucestershire",Table1[[#This Row],[income]],0) -> 0 | BS10: =IF(Table1[[#This Row],[County]]="West Sussex",Table1[[#This Row],[income]],0) -> 0 | BT10: =IF(Table1[[#This Row],[County]]="Devon",Table1[[#This Row],[income]],0) -> 0 | BU10: =IF(Table1[[#This Row],[County]]="Berkshire",Table1[[#This Row],[income]],0) -> 0 | BV10: =IF(Table1[[#This Row],[County]]="Staffordshire",Table1[[#This Row],[income]],0) -> 0 | BW10: =IF(Table1[[#This Row],[County]]="Leicestershire",Table1[[#This Row],[income]],0) -> 0 | BX10: =IF(Table1[[#This Row],[County]]="Cornwall",Table1[[#This Row],[income]],0) -> 0 | BY10: =IF(Table1[[#This Row],[County]]="Isle of Wight",Table1[[#This Row],[income]],0) -> 0 | BZ10: =IF(Table1[[#This Row],[County]]="Surrey",Table1[[#This Row],[income]],0) -> 0 | CA10: =IF(Table1[[#This Row],[County]]="Derbyshire",Table1[[#This Row],[income]],0) -> 0 | CB10: =IF(Table1[[#This Row],[County]]="City of London",Table1[[#This Row],[income]],0) -> 0 | CC10: =IF(Table1[[#This Row],[County]]="Bedfordshire",Table1[[#This Row],[income]],0) -> 0 | CD10: =IF(Table1[[#This Row],[County]]="County Durham",Table1[[#This Row],[income]],0) -> 0 | CE10: =IF(Table1[[#This Row],[County]]="East Riding of Yorkshire",Table1[[#This Row],[income]],0) -> 0 | CF10: =IF(Table1[[#This Row],[County]]="West Yorkshire",Table1[[#This Row],[income]],0) -> 0 | CG10: =IF(Table1[[#This Row],[County]]="Essex",Table1[[#This Row],[income]],0) -> 0 | CH10: =IF(Table1[[#This Row],[County]]="East Sussex",Table1[[#This Row],[income]],0) -> 0 | CI10: =IF(Table1[[#This Row],[County]]="Greater Manchester",Table1[[#This Row],[income]],0) -> 0 | CJ10: =IF(Table1[[#This Row],[County]]="Hertfordshire",Table1[[#This Row],[income]],0) -> 0 | CK10: =IF(Table1[[#This Row],[County]]="Herefordshire",Table1[[#This Row],[income]],0) -> 0 | CL10: =IF(Table1[[#This Row],[County]]="Lancashire",Table1[[#This Row],[income]],0) -> 0 | CM10: =IF(Table1[[#This Row],[County]]="Merseyside",Table1[[#This Row],[income]],0) -> 0 | CN10: =IF(Table1[[#This Row],[County]]="Northamptonshire",Table1[[#This Row],[income]],0) -> 0 | CO10: =IF(Table1[[#This Row],[County]]="Northumberland",Table1[[#This Row],[income]],0) -> 0 | CP10: =IF(Table1[[#This Row],[County]]="Wiltshire",Table1[[#This Row],[income]],0) -> 0 | CQ10: =IF(Table1[[#This Row],[County]]="West Midlands",Table1[[#This Row],[income]],0) -> 79805 | CR10: =IF(Table1[[#This Row],[County]]="Warwickshire",Table1[[#This Row],[income]],0) -> 0 | CS10: =IF(Table1[[#This Row],[County]]="Tyne and Wear",Table1[[#This Row],[income]],0) -> 0 | CT10: =IF(Table1[[#This Row],[County]]="Worcestershire",Table1[[#This Row],[income]],0) -> 0 | CU10: =IF(Table1[[#This Row],[County]]="Rutland",Table1[[#This Row],[income]],0) -> 0 | CV10: =IF(Table1[[#This Row],[County]]="Shropshire",Table1[[#This Row],[income]],0) -> 0 | CW10: =IF(Table1[[#This Row],[County]]="Dorset",Table1[[#This Row],[income]],0) -> 0 | CX10: =IF(Table1[[#This Row],[County]]="Buckinghamshire",Table1[[#This Row],[income]],0) -> 0 | CY10: =IF(Table1[[#This Row],[County]]="Suffolk",Table1[[#This Row],[income]],0) -> 0 | CZ10: =IF(Table1[[#This Row],[County]]="North Yorkshire",Table1[[#This Row],[income]],0) -> 0 | DA10: =IF(Table1[[#This Row],[County]]="Kent",Table1[[#This Row],[income]],0) -> 0 | DB10: =IF(Table1[[#This Row],[County]]="Derbyshire",Table1[[#This Row],[income]],0) -> 0 | DD10: =IF(Table1[[#This Row],[Column1]]="Health",Table1[[#This Row],[income]],0) -> 0 | DE10: =IF(Table1[[#This Row],[Column1]]="Agriculture",Table1[[#This Row],[income]],0) -> 79805 | DF10: =IF(Table1[[#This Row],[Column1]]="Technology",Table1[[#This Row],[income]],0) -> 0 | DG10: =IF(Table1[[#This Row],[Column1]]="Social Service",Table1[[#This Row],[income]],0) -> 0 | DH10: =IF(Table1[[#This Row],[Column1]]="Education",Table1[[#This Row],[income]],0) -> 0 | DI10: =IF(Table1[[#This Row],[Column1]]="Construction",Table1[[#This Row],[income]],0) -> 0 | DK10: =IF(Table1[[#This Row],[Value of Debts]]>Table1[[#This Row],[income]],1,0) -> 1 | DP10: =IF(Table1[[#This Row],[Net Worth (£)]]>$DS$5,C10,0) -> 50
A11: =RANDBETWEEN(1,2) -> 2 | B11: =IF(A11=1, "men", "women") -> women | C11: =RANDBETWEEN(25,50) -> 30 | D11: =RANDBETWEEN(1,6) -> 3 | E11: =VLOOKUP(D11,$W$5:$X$10,2) -> Education | F11: =RANDBETWEEN(1,5) -> 2 | G11: =VLOOKUP(F11,$Y$5:$Z$9,2) -> College | H11: =RANDBETWEEN(0,4) -> 3 | I11: =RANDBETWEEN(1,3) -> 3 | J11: =RANDBETWEEN(30000,100000) -> 80518 | K11: =RANDBETWEEN(1,48) -> 43 | L11: =VLOOKUP(K11,$AA$5:$AB$52,2) -> Warwickshire | M11: =J11*(RANDBETWEEN(2,5)) -> 161036 | N11: =RAND()*M11 -> 138535.83 | O11: =I11*RAND()*J11 -> 12758.929 | P11: =RANDBETWEEN(0,O11) -> 10499 | Q11: =RAND()*J11*2 -> 76780.564 | R11: =RAND()*J11*1.5 -> 27993.553 | S11: =J11+R11+O11 -> 121270.48 | T11: =N11+P11+Q11 -> 225815.39 | U11: =S11-T11 -> -104544.91 | AA11: 7 | AB11: City of London | AC11: =IF(Table1[[#This Row],[gender]]="men",1,0) -> 0 | AD11: =IF(Table1[[#This Row],[gender]]="women",1,0) -> 1 | AJ11: =IF(Table1[[#This Row],[Column1]]="Health",1,0) -> 0 | AK11: =IF(Table1[[#This Row],[Column1]]="Construction",1,0) -> 0 | AL11: =IF(Table1[[#This Row],[Column1]]="Technology",1,0) -> 0 | AM11: =IF(Table1[[#This Row],[Column1]]="Education",1,0) -> 1 | AN11: =IF(Table1[[#This Row],[Column1]]="Agriculture",1,0) -> 0 | AO11: =IF(Table1[[#This Row],[Column1]]="Social Service", 1, 0) -> 0 | AV11: =(O12/I12) -> 50980.657 | AX11: =IF(Table1[[#This Row],[Value of Debts]]>$AY$4,1,0) -> 1 | BB11: =Table1[[#This Row],[Mortage Left]]/Table1[[#This Row],[Value of House]] -> 0.86027862 | BC11: =IF(BB11<$BD$4,1,0) -> 0 | BG11: =IF(Table1[[#This Row],[County]]="Cumbria",Table1[[#This Row],[income]],0) -> 0 | BH11: =IF(Table1[[#This Row],[County]]="Cheshire",Table1[[#This Row],[income]],0) -> 0 | BI11: =IF(Table1[[#This Row],[County]]="Bristol",Table1[[#This Row],[income]],0) -> 0 | BJ11: =IF(Table1[[#This Row],[County]]="Surrey",Table1[[#This Row],[income]],0) -> 0 | BK11: =IF(Table1[[#This Row],[County]]="Norfolk",Table1[[#This Row],[income]],0) -> 0 | BL11: =IF(Table1[[#This Row],[County]]="Lincolnshire",Table1[[#This Row],[income]],0) -> 0 | BM11: =IF(Table1[[#This Row],[County]]="Somerset",Table1[[#This Row],[income]],0) -> 0 | BN11: =IF(Table1[[#This Row],[County]]="Cambridgeshire",Table1[[#This Row],[income]],0) -> 0 | BO11: =IF(Table1[[#This Row],[County]]="South Yorkshire",Table1[[#This Row],[income]],0) -> 0 | BP11: =IF(Table1[[#This Row],[County]]="Greater London",Table1[[#This Row],[income]],0) -> 0 | BQ11: =IF(Table1[[#This Row],[County]]="Hampshire",Table1[[#This Row],[income]],0) -> 0 | BR11: =IF(Table1[[#This Row],[County]]="Gloucestershire",Table1[[#This Row],[income]],0) -> 0 | BS11: =IF(Table1[[#This Row],[County]]="West Sussex",Table1[[#This Row],[income]],0) -> 0 | BT11: =IF(Table1[[#This Row],[County]]="Devon",Table1[[#This Row],[income]],0) -> 0 | BU11: =IF(Table1[[#This Row],[County]]="Berkshire",Table1[[#This Row],[income]],0) -> 0 | BV11: =IF(Table1[[#This Row],[County]]="Staffordshire",Table1[[#This Row],[income]],0) -> 0 | BW11: =IF(Table1[[#This Row],[County]]="Leicestershire",Table1[[#This Row],[income]],0) -> 0 | BX11: =IF(Table1[[#This Row],[County]]="Cornwall",Table1[[#This Row],[income]],0) -> 0 | BY11: =IF(Table1[[#This Row],[County]]="Isle of Wight",Table1[[#This Row],[income]],0) -> 0 | BZ11: =IF(Table1[[#This Row],[County]]="Surrey",Table1[[#This Row],[income]],0) -> 0 | CA11: =IF(Table1[[#This Row],[County]]="Derbyshire",Table1[[#This Row],[income]],0) -> 0 | CB11: =IF(Table1[[#This Row],[County]]="City of London",Table1[[#This Row],[income]],0) -> 0 | CC11: =IF(Table1[[#This Row],[County]]="Bedfordshire",Table1[[#This Row],[income]],0) -> 0 | CD11: =IF(Table1[[#This Row],[County]]="County Durham",Table1[[#This Row],[income]],0) -> 0 | CE11: =IF(Table1[[#This Row],[County]]="East Riding of Yorkshire",Table1[[#This Row],[income]],0) -> 0 | CF11: =IF(Table1[[#This Row],[County]]="West Yorkshire",Table1[[#This Row],[income]],0) -> 0 | CG11: =IF(Table1[[#This Row],[County]]="Essex",Table1[[#This Row],[income]],0) -> 0 | CH11: =IF(Table1[[#This Row],[County]]="East Sussex",Table1[[#This Row],[income]],0) -> 0 | CI11: =IF(Table1[[#This Row],[County]]="Greater Manchester",Table1[[#This Row],[income]],0) -> 0 | CJ11: =IF(Table1[[#This Row],[County]]="Hertfordshire",Table1[[#This Row],[income]],0) -> 0 | CK11: =IF(Table1[[#This Row],[County]]="Herefordshire",Table1[[#This Row],[income]],0) -> 0 | CL11: =IF(Table1[[#This Row],[County]]="Lancashire",Table1[[#This Row],[income]],0) -> 0 | CM11: =IF(Table1[[#This Row],[County]]="Merseyside",Table1[[#This Row],[income]],0) -> 0 | CN11: =IF(Table1[[#This Row],[County]]="Northamptonshire",Table1[[#This Row],[income]],0) -> 0 | CO11: =IF(Table1[[#This Row],[County]]="Northumberland",Table1[[#This Row],[income]],0) -> 0 | CP11: =IF(Table1[[#This Row],[County]]="Wiltshire",Table1[[#This Row],[income]],0) -> 0 | CQ11: =IF(Table1[[#This Row],[County]]="West Midlands",Table1[[#This Row],[income]],0) -> 0 | CR11: =IF(Table1[[#This Row],[County]]="Warwickshire",Table1[[#This Row],[income]],0) -> 80518 | CS11: =IF(Table1[[#This Row],[County]]="Tyne and Wear",Table1[[#This Row],[income]],0) -> 0 | CT11: =IF(Table1[[#This Row],[County]]="Worcestershire",Table1[[#This Row],[income]],0) -> 0 | CU11: =IF(Table1[[#This Row],[County]]="Rutland",Table1[[#This Row],[income]],0) -> 0 | CV11: =IF(Table1[[#This Row],[County]]="Shropshire",Table1[[#This Row],[income]],0) -> 0 | CW11: =IF(Table1[[#This Row],[County]]="Dorset",Table1[[#This Row],[income]],0) -> 0 | CX11: =IF(Table1[[#This Row],[County]]="Buckinghamshire",Table1[[#This Row],[income]],0) -> 0 | CY11: =IF(Table1[[#This Row],[County]]="Suffolk",Table1[[#This Row],[income]],0) -> 0 | CZ11: =IF(Table1[[#This Row],[County]]="North Yorkshire",Table1[[#This Row],[income]],0) -> 0 | DA11: =IF(Table1[[#This Row],[County]]="Kent",Table1[[#This Row],[income]],0) -> 0 | DB11: =IF(Table1[[#This Row],[County]]="Derbyshire",Table1[[#This Row],[income]],0) -> 0 | DD11: =IF(Table1[[#This Row],[Column1]]="Health",Table1[[#This Row],[income]],0) -> 0 | DE11: =IF(Table1[[#This Row],[Column1]]="Agriculture",Table1[[#This Row],[income]],0) -> 0 | DF11: =IF(Table1[[#This Row],[Column1]]="Technology",Table1[[#This Row],[income]],0) -> 0 | DG11: =IF(Table1[[#This Row],[Column1]]="Social Service",Table1[[#This Row],[income]],0) -> 0 | DH11: =IF(Table1[[#This Row],[Column1]]="Education",Table1[[#This Row],[income]],0) -> 80518 | DI11: =IF(Table1[[#This Row],[Column1]]="Construction",Table1[[#This Row],[income]],0) -> 0 | DK11: =IF(Table1[[#This Row],[Value of Debts]]>Table1[[#This Row],[income]],1,0) -> 1 | DP11: =IF(Table1[[#This Row],[Net Worth (£)]]>$DS$5,C11,0) -> 0
A12: =RANDBETWEEN(1,2) -> 1 | B12: =IF(A12=1, "men", "women") -> men | C12: =RANDBETWEEN(25,50) -> 25 | D12: =RANDBETWEEN(1,6) -> 4 | E12: =VLOOKUP(D12,$W$5:$X$10,2) -> Technology | F12: =RANDBETWEEN(1,5) -> 4 | G12: =VLOOKUP(F12,$Y$5:$Z$9,2) -> Technical | H12: =RANDBETWEEN(0,4) -> 1 | I12: =RANDBETWEEN(1,3) -> 2 | J12: =RANDBETWEEN(30000,100000) -> 81204 | K12: =RANDBETWEEN(1,48) -> 28 | L12: =VLOOKUP(K12,$AA$5:$AB$52,2) -> Lincolnshire | M12: =J12*(RANDBETWEEN(2,5)) -> 162408 | N12: =RAND()*M12 -> 6855.2264 | O12: =I12*RAND()*J12 -> 101961.31 | P12: =RANDBETWEEN(0,O12) -> 53410 | Q12: =RAND()*J12*2 -> 82184.039 | R12: =RAND()*J12*1.5 -> 68255.562 | S12: =J12+R12+O12 -> 251420.88 | T12: =N12+P12+Q12 -> 142449.27 | U12: =S12-T12 -> 108971.61 | AA12: 8 | AB12: Cornwall | AC12: =IF(Table1[[#This Row],[gender]]="men",1,0) -> 1 | AD12: =IF(Table1[[#This Row],[gender]]="women",1,0) -> 0 | AJ12: =IF(Table1[[#This Row],[Column1]]="Health",1,0) -> 0 | AK12: =IF(Table1[[#This Row],[Column1]]="Construction",1,0) -> 0 | AL12: =IF(Table1[[#This Row],[Column1]]="Technology",1,0) -> 1 | AM12: =IF(Table1[[#This Row],[Column1]]="Education",1,0) -> 0 | AN12: =IF(Table1[[#This Row],[Column1]]="Agriculture",1,0) -> 0 | AO12: =IF(Table1[[#This Row],[Column1]]="Social Service", 1, 0) -> 0 | AV12: =(O13/I13) -> 86747.808 | AX12: =IF(Table1[[#This Row],[Value of Debts]]>$AY$4,1,0) -> 1 | BB12: =Table1[[#This Row],[Mortage Left]]/Table1[[#This Row],[Value of House]] -> 0.042209906 | BC12: =IF(BB12<$BD$4,1,0) -> 1 | BG12: =IF(Table1[[#This Row],[County]]="Cumbria",Table1[[#This Row],[income]],0) -> 0 | BH12: =IF(Table1[[#This Row],[County]]="Cheshire",Table1[[#This Row],[income]],0) -> 0 | BI12: =IF(Table1[[#This Row],[County]]="Bristol",Table1[[#This Row],[income]],0) -> 0 | BJ12: =IF(Table1[[#This Row],[County]]="Surrey",Table1[[#This Row],[income]],0) -> 0 | BK12: =IF(Table1[[#This Row],[County]]="Norfolk",Table1[[#This Row],[income]],0) -> 0 | BL12: =IF(Table1[[#This Row],[County]]="Lincolnshire",Table1[[#This Row],[income]],0) -> 81204 | BM12: =IF(Table1[[#This Row],[County]]="Somerset",Table1[[#This Row],[income]],0) -> 0 | BN12: =IF(Table1[[#This Row],[County]]="Cambridgeshire",Table1[[#This Row],[income]],0) -> 0 | BO12: =IF(Table1[[#This Row],[County]]="South Yorkshire",Table1[[#This Row],[income]],0) -> 0 | BP12: =IF(Table1[[#This Row],[County]]="Greater London",Table1[[#This Row],[income]],0) -> 0 | BQ12: =IF(Table1[[#This Row],[County]]="Hampshire",Table1[[#This Row],[income]],0) -> 0 | BR12: =IF(Table1[[#This Row],[County]]="Gloucestershire",Table1[[#This Row],[income]],0) -> 0 | BS12: =IF(Table1[[#This Row],[County]]="West Sussex",Table1[[#This Row],[income]],0) -> 0 | BT12: =IF(Table1[[#This Row],[County]]="Devon",Table1[[#This Row],[income]],0) -> 0 | BU12: =IF(Table1[[#This Row],[County]]="Berkshire",Table1[[#This Row],[income]],0) -> 0 | BV12: =IF(Table1[[#This Row],[County]]="Staffordshire",Table1[[#This Row],[income]],0) -> 0 | BW12: =IF(Table1[[#This Row],[County]]="Leicestershire",Table1[[#This Row],[income]],0) -> 0 | BX12: =IF(Table1[[#This Row],[County]]="Cornwall",Table1[[#This Row],[income]],0) -> 0 | BY12: =IF(Table1[[#This Row],[County]]="Isle of Wight",Table1[[#This Row],[income]],0) -> 0 | BZ12: =IF(Table1[[#This Row],[County]]="Surrey",Table1[[#This Row],[income]],0) -> 0 | CA12: =IF(Table1[[#This Row],[County]]="Derbyshire",Table1[[#This Row],[income]],0) -> 0 | CB12: =IF(Table1[[#This Row],[County]]="City of London",Table1[[#This Row],[income]],0) -> 0 | CC12: =IF(Table1[[#This Row],[County]]="Bedfordshire",Table1[[#This Row],[income]],0) -> 0 | CD12: =IF(Table1[[#This Row],[County]]="County Durham",Table1[[#This Row],[income]],0) -> 0 | CE12: =IF(Table1[[#This Row],[County]]="East Riding of Yorkshire",Table1[[#This Row],[income]],0) -> 0 | CF12: =IF(Table1[[#This Row],[County]]="West Yorkshire",Table1[[#This Row],[income]],0) -> 0 | CG12: =IF(Table1[[#This Row],[County]]="Essex",Table1[[#This Row],[income]],0) -> 0 | CH12: =IF(Table1[[#This Row],[County]]="East Sussex",Table1[[#This Row],[income]],0) -> 0 | CI12: =IF(Table1[[#This Row],[County]]="Greater Manchester",Table1[[#This Row],[income]],0) -> 0 | CJ12: =IF(Table1[[#This Row],[County]]="Hertfordshire",Table1[[#This Row],[income]],0) -> 0 | CK12: =IF(Table1[[#This Row],[County]]="Herefordshire",Table1[[#This Row],[income]],0) -> 0 | CL12: =IF(Table1[[#This Row],[County]]="Lancashire",Table1[[#This Row],[income]],0) -> 0 | CM12: =IF(Table1[[#This Row],[County]]="Merseyside",Table1[[#This Row],[income]],0) -> 0 | CN12: =IF(Table1[[#This Row],[County]]="Northamptonshire",Table1[[#This Row],[income]],0) -> 0 | CO12: =IF(Table1[[#This Row],[County]]="Northumberland",Table1[[#This Row],[income]],0) -> 0 | CP12: =IF(Table1[[#This Row],[County]]="Wiltshire",Table1[[#This Row],[income]],0) -> 0 | CQ12: =IF(Table1[[#This Row],[County]]="West Midlands",Table1[[#This Row],[income]],0) -> 0 | CR12: =IF(Table1[[#This Row],[County]]="Warwickshire",Table1[[#This Row],[income]],0) -> 0 | CS12: =IF(Table1[[#This Row],[County]]="Tyne and Wear",Table1[[#This Row],[income]],0) -> 0 | CT12: =IF(Table1[[#This Row],[County]]="Worcestershire",Table1[[#This Row],[income]],0) -> 0 | CU12: =IF(Table1[[#This Row],[County]]="Rutland",Table1[[#This Row],[income]],0) -> 0 | CV12: =IF(Table1[[#This Row],[County]]="Shropshire",Table1[[#This Row],[income]],0) -> 0 | CW12: =IF(Table1[[#This Row],[County]]="Dorset",Table1[[#This Row],[income]],0) -> 0 | CX12: =IF(Table1[[#This Row],[County]]="Buckinghamshire",Table1[[#This Row],[income]],0) -> 0 | CY12: =IF(Table1[[#This Row],[County]]="Suffolk",Table1[[#This Row],[income]],0) -> 0 | CZ12: =IF(Table1[[#This Row],[County]]="North Yorkshire",Table1[[#This Row],[income]],0) -> 0 | DA12: =IF(Table1[[#This Row],[County]]="Kent",Table1[[#This Row],[income]],0) -> 0 | DB12: =IF(Table1[[#This Row],[County]]="Derbyshire",Table1[[#This Row],[income]],0) -> 0 | DD12: =IF(Table1[[#This Row],[Column1]]="Health",Table1[[#This Row],[income]],0) -> 0 | DE12: =IF(Table1[[#This Row],[Column1]]="Agriculture",Table1[[#This Row],[income]],0) -> 0 | DF12: =IF(Table1[[#This Row],[Column1]]="Technology",Table1[[#This Row],[income]],0) -> 81204 | DG12: =IF(Table1[[#This Row],[Column1]]="Social Service",Table1[[#This Row],[income]],0) -> 0 | DH12: =IF(Table1[[#This Row],[Column1]]="Education",Table1[[#This Row],[income]],0) -> 0 | DI12: =IF(Table1[[#This Row],[Column1]]="Construction",Table1[[#This Row],[income]],0) -> 0 | DK12: =IF(Table1[[#This Row],[Value of Debts]]>Table1[[#This Row],[income]],1,0) -> 1 | DP12: =IF(Table1[[#This Row],[Net Worth (£)]]>$DS$5,C12,0) -> 25
